Workbook

Sheet Start Here
A1: PakFreight Star Builder — Week 3 Activity
A2: Data Warehousing & Business Intelligence · Week 3 — Fact & Dimension Tables · CLO2 · The Superior University, Lahore
A4: THE SITUATION
A5: Week 2 ended with one flat table: Shipments_Unified, 34 rows, 578,650 kg, PKR 4,808,000. It answers simple questions and fails at every interesting one — there is no province column, no month column, Karachi is spelled five different ways, and nothing in it remembers what a route used to be called. Today you split it into one fact table and five dimensions, and the totals must not move by a single kilogram.
A7: HOW TO WORK
A8: • Teams of 3. Name one person each: Modeller (owns the grain), Conformer (owns DimCity), Reconciler (owns T7 and has veto power over 'it looks fine').
A9: • Do the tasks in order. T6 cannot be filled in before T4 and T5 exist — that is not a quirk of this workbook, it is why dimensions are always loaded before facts.
A10: • Type only in CREAM cells. GREY cells are source data as received — never edit them.
A11: • T7 marks itself. Every '✘ fix' means something earlier is still wrong. Do not submit with a red cell and a hopeful note.
A12: • Save as W3_Star_<team number>.xlsx and submit on the LMS before Week 4, with the Power BI file described in PakFreight_W3_PowerBI_Lab_Guide.md.
A14: THE SEVEN TASKS
A15: # | B15: Task | C15: What you produce | D15: 180-min class | E15: 120-min class | F15: Where it comes from in the lecture
A16: T1 | B16: Classify every column | C16: Fact, dimension attribute, degenerate or drop | D16: 10 | E16: 8 | F16: Slides 9-17 · what belongs where
A17: T2 | B17: Declare the grain | C17: One sentence, no 'and' — for PakFreight and 4 new processes | D17: 12 | E17: 10 | F17: Slides 19-24 · Kimball's four steps
A18: T3 | B18: Additivity audit | C18: Additive, semi-additive, non-additive — and prove the ratio trap | D18: 10 | E18: 7 | F18: Slide 10 · 8.06 vs 8.31
A19: T4 | B19: Build DimCity | C19: Conform 23 raw location strings into 14 cities, mint the keys | D19: 20 | E19: 15 | F19: Slides 11, 30, 43 · surrogate keys
A20: T5 | B20: Build the other four dimensions | C20: DimRoute, DimMode, DimStatus, DimDate | D20: 20 | E20: 15 | F20: Slides 31-34, 38, 44
A21: T6 | B21: Build FactShipment | C21: Swap every text column for an integer key | D21: 15 | E21: 12 | F21: Slides 9, 44 · merge on the key only
A22: T7 | B22: Reconcile | C22: Thirteen checks. All thirteen must read 'pass' | D22: 8 | E22: 8 | F22: Slide 46 · validate before you trust
C23: Total minutes | D23: 95 | E23: 75
A25: COLOUR LEGEND
B26: You type here
B27: Source data — do not edit
B28: ✔ pass — check satisfied
B29: ✘ fix — go back and correct it
B30: Model answer (teacher key only)
A32: THE GRAIN CONTRACT — WRITE IT ONCE, OBEY IT EVERYWHERE
B33: Decision | C33: Your answer (T2 fills this in) | F33: Why it matters
B34: Business process | C34: Freight shipment movement | F34: Step 1 of Kimball's four steps — pick a process, not a department.
B35: Grain (one row = ?) | F35: Step 2. If your sentence needs the word 'and', you have two fact tables.
B36: Fact table type | F36: Transaction, periodic snapshot or accumulating snapshot.
B37: Dimensions | F37: Step 3 — and they must follow from the grain, not from your imagination.
B38: Measures | F38: Step 4 — additive wherever you can manage it.

Sheet Shipments_Unified
A1: Shipments_Unified — the Week 2 output
A2: 34 rows · 578,650 kg · PKR 4,808,000. Grey means source data: read it, point formulas at it, never edit it. This whole sheet becomes FactShipment in T6.
A4: ShipmentID | B4: ShipDate | C4: Origin | D4: Destination | E4: WeightKG | F4: CostPKR | G4: Status | H4: SourceSystem
A5: MR-1001 | B5: 46054 | C5: Karachi Port | D5: Lahore Dry Port | E5: 18000 | F5: 142000 | G5: Delivered | H5: Marine
A6: MR-1002 | B6: 46055 | C6: Port Qasim | D6: Faisalabad Dry Port | E6: 22500 | F6: 171000 | G6: Delivered | H6: Marine
A7: MR-1003 | B7: 46056 | C7: Karachi Port | D7: Lahore Dry Port | E7: 15000 | F7: 119000 | G7: In Transit | H7: Marine
A8: MR-1004 | B8: 46057 | C8: Gwadar Port | D8: Quetta | E8: 20000 | F8: 188000 | G8: Delivered | H8: Marine
A9: MR-1005 | B9: 46058 | C9: Port Qasim | D9: Multan | E9: 16500 | F9: 128000 | G9: Delivered | H9: Marine
A10: MR-1006 | B10: 46059 | C10: Karachi Port | D10: Sialkot Dry Port | E10: 19000 | F10: 154000 | G10: Delayed | H10: Marine
A11: MR-1007 | B11: 46060 | C11: Port Qasim | D11: Lahore Dry Port | E11: 14000 | F11: 109000 | G11: Delivered | H11: Marine
A12: MR-1008 | B12: 46062 | C12: Karachi Port | D12: Peshawar | E12: 21000 | F12: 197000 | G12: In Transit | H12: Marine
A13: MR-1009 | B13: 46063 | C13: Gwadar Port | D13: Karachi Cantt | E13: 17500 | F13: 98000 | G13: Delivered | H13: Marine
A14: MR-1010 | B14: 46064 | C14: Port Qasim | D14: Islamabad Dry Port | E14: 15500 | F14: 139000 | G14: Delivered | H14: Marine
A15: MR-1011 | B15: 46065 | C15: Karachi Port | D15: Hyderabad | E15: 13500 | F15: 61000 | G15: In Transit | H15: Marine
A16: MR-1012 | B16: 46066 | C16: Port Qasim | D16: Lahore Dry Port | E16: 14000 | F16: 112000 | G16: Delivered | H16: Marine
... A38: RD-512 | B38: 46066 | C38: Rawalpindi | D38: Abbottabad | E38: 5800 | F38: 45000 | G38: Delivered | H38: Road
D39: TOTAL | E39: =SUM(E5:E38) | F39: =SUM(F5:F38)
A41: Count the distinct dates in column B. There are 12 — not 28. February 2026 has 28 days and PakFreight dispatched nothing on 16 of them. Any 'average per day' computed from this sheet divides by the wrong number, silently. That is what DimDate in T5 is for.

Sheet T1 Classify
A1: T1 · Fact, Dimension, Degenerate or Drop?
A2: PakFreight's operations team wants twelve more columns added to the warehouse. For each one write F (fact / measure), D (dimension attribute), DD (degenerate dimension) or X (belongs in neither), name the table it should live in, and defend it in one line. Four of the twelve are deliberately tricky.
A4: # | B4: Column the team asked for | C4: F / D / DD / X | D4: Which table does it live in? | E4: Your one-line justification
A5: 1 | B5: Driver_Name
A6: 2 | B6: Days_Late
A7: 3 | B7: Invoice_Number
A8: 4 | B8: Discount_Percent
A9: 5 | B9: Truck_Registration_No
A10: 6 | B10: Container_Count
A11: 7 | B11: Customer_Credit_Rating
A12: 8 | B12: Cost_Per_Tonne_KM
A13: 9 | B13: Row_Inserted_Timestamp
A14: 10 | B14: Fuel_Surcharge_PKR
A15: 11 | B15: Weather_Condition
A16: 12 | B16: Is_Hazardous_Cargo
B17: Answered so far | C17: =COUNTA(C5:C16)&" / 12"
A19: DEFEND YOUR ANSWERS — THE THREE QUESTIONS WE WILL ASK
A20: Which of your X answers would a real analyst fight you over, and what is their best argument?
A22: Name one column you marked D that deserves its own dimension table, and three attributes it would carry.
A24: If Days_Late is a fact, which dimension supplies the deadline it is measured against?
A27: Marking: 6 marks for the twelve verdicts (half a mark each), 3 marks for the justifications, 3 marks for the three questions. A wrong verdict with a sharp justification scores more than a right verdict with none — the reasoning is the skill.

Sheet T2 Grain
A1: T2 · Declare the Grain
A2: The single most consequential sentence in warehouse design. Write it for PakFreight, then for four processes PakFreight wants to add next. Use the template: 'One row per …'. If your sentence needs the word 'and', you have described two fact tables.
A4: PART A · THE PAKFREIGHT GRAIN STATEMENT
B5: One row of FactShipment represents… | F5: =IF(C5="","— not written yet",IF(ISNUMBER(SEARCH(" and ",C5)),"✘ contains 'and' — that is two fact tables","✔ no 'and' — one grain"))
A6: Why 'leg' and not 'shipment'? MR-1009 moves Gwadar → Karachi and RD-508 moves Quetta → Karachi. If a single customer consignment is later carried marine-then-road, 'one row per shipment' becomes ambiguous the day PakFreight sells multi-modal freight — and the grain you declare today is the one the CFO's 2027 reports will be built on.
A8: PART B · FOUR NEW PROCESSES — GRAIN, DIMENSIONS, MEASURES, FACT TYPE
A9: # | B9: Business process | C9: Grain sentence (one row per …) | D9: Dimensions it implies | E9: Two measures | F9: Fact table type + why
A10: 1 | B10: Fuel purchases at PakFreight depots
B11: Hint: Is the grain one fuel purchase, one litre, or one truck per week?
A12: 2 | B12: Driver duty hours and rest compliance
B13: Hint: Regulators care about a rolling 14-day window. Does that change the grain, or only the measures?
A14: 3 | B14: Customer complaints about late delivery
B15: Hint: One complaint can reference several shipments. Where does that relationship live?
A16: 4 | B16: Daily warehouse stock levels at Lahore Dry Port
B17: Hint: Nothing 'happens' on a quiet day — but you still need a number. Which fact shape is this?
A19: PART C · THE GRAIN THAT WENT WRONG — A 20-SECOND CASE
B20: A PakFreight analyst needs cost per customer, so he adds CustomerName to FactShipment. Two shipments on RD-501 are billed to two customers who split the truck. He cannot choose, so he duplicates the row — once per customer. The table now has 35 rows, total weight reads 585,150 kg, and every weight report in the company is overstated by 6,500 kg forever. In one line each: (a) what rule did he break? (b) what should he have built instead? (c) which of T7's twelve checks would have caught it?
A26: Marking, 12 marks: Part A grain sentence 3 · Part B 1.5 per process (grain 0.75, dimensions 0.5, measures 0.25) · Part C 3 · bonus 1 for spotting that #4 is a periodic snapshot and #3 needs a bridge table. A sentence containing 'and' loses the grain mark however good the rest is.

Sheet T3 Additivity
A1: T3 · Additivity Audit — and the ratio that lies by 3%
A2: A measure is only useful once you know which dimensions you may add it across. Classify ten measures, then prove the ratio trap on PakFreight's own 34 rows.
A4: # | B4: Candidate measure | C4: Additive / Semi / Non | D4: Safe to SUM across time? | E4: What should you store instead? | F4: Notes / your reasoning
A5: 1 | B5: WeightKG
A6: 2 | B6: FreightCostPKR
A7: 3 | B7: ShipmentCount (=1)
A8: 4 | B8: TrucksAvailable at a depot
A9: 5 | B9: WarehouseStockKG
A10: 6 | B10: CostPerKG
A11: 7 | B11: OnTimePercent
A12: 8 | B12: TruckUtilisationRate
A13: 9 | B13: Days_Late
A14: 10 | B14: AverageWeightPerShipment
A16: THE PROOF · AVERAGE OF A RATIO vs RATIO OF TWO SUMS — SAME 34 ROWS, TWO DIFFERENT ANSWERS
B17: WRONG — average the per-row ratio | C17: =SUMPRODUCT(Shipments_Unified!F5:F38/Shipments_Unified!E5:E38)/34 | D17: What AVERAGE(Cost/Weight) gives you, and what a careless DAX measure gives you.
B18: RIGHT — divide the two sums | C18: =SUM(Shipments_Unified!F5:F38)/SUM(Shipments_Unified!E5:E38) | D18: What DIVIDE(SUM(Cost), SUM(Weight)) gives you. The only version that is correct at every level.
B19: The gap, in PKR per kg | C19: =C18-C17 | D19: Small enough that nobody notices. On PakFreight's real annual volume it is tens of millions.
B20: The gap, as a percentage | C20: =(C18-C17)/C17 | D20: No error is raised. No cell turns red. The number is simply wrong.
B21: Expected: 8.0604 (wrong) and 8.3090 (right)
A23: ANSWER IN ONE LINE EACH
B24: Which of the two numbers above would you put on a board slide, and what exactly does the other one measure?
B26: PakFreight's CFO asks for 'average cost per kg by province'. Write the rule you will follow so the provincial numbers still roll up to the national one.
B28: Name the one measure in the table above whose correct answer is 'delete the column', and say why a stored average can never be fixed later.
A31: Marking, 10 marks: classification 5 (half a mark per row) · 'store instead' column 2 · the three questions 3. Full marks on question 1 require naming what 8.06 actually measures — 'it is wrong' is not an answer.

Sheet T4 DimCity
A1: T4 · Conform 23 Location Strings into 14 Cities
A2: This is the editorial act of dimensional modelling, and it is yours. Block 1: decide what each raw string really is. Block 2: build the dimension, one row per real-world city, with a surrogate key you mint yourself.
A4: BLOCK 1 · THE CONFORMING MAP — 23 RAW STRINGS, EXACTLY AS THE SOURCE SYSTEMS WROTE THEM
A5: # | B5: Raw location string (grey — do not edit) | C5: Conformed CityName | D5: Province | E5: Region | F5: Port city? | G5: Facility type | I5: CityKey | J5: CityName | K5: Province | L5: Region | M5: Port? | N5: FacilityType | O5: SourceAliases (which raw strings map here)
A6: 1 | B6: Karachi Port | I6: 1 | K6: =IF($J6="","",IFERROR(INDEX(D$6:D$28,MATCH($J6,$C$6:$C$28,0)),"?")) | L6: =IF($J6="","",IFERROR(INDEX(E$6:E$28,MATCH($J6,$C$6:$C$28,0)),"?")) | M6: =IF($J6="","",IFERROR(INDEX(F$6:F$28,MATCH($J6,$C$6:$C$28,0)),"?")) | N6: =IF($J6="","",IFERROR(INDEX(G$6:G$28,MATCH($J6,$C$6:$C$28,0)),"?")) | O6: =IF($J6="","",TEXTJOIN(" | ",TRUE,IF($C$6:$C$28=$J6,$B$6:$B$28,"")))
A7: 2 | B7: Port Qasim | I7: 2 | K7: =IF($J7="","",IFERROR(INDEX(D$6:D$28,MATCH($J7,$C$6:$C$28,0)),"?")) | L7: =IF($J7="","",IFERROR(INDEX(E$6:E$28,MATCH($J7,$C$6:$C$28,0)),"?")) | M7: =IF($J7="","",IFERROR(INDEX(F$6:F$28,MATCH($J7,$C$6:$C$28,0)),"?")) | N7: =IF($J7="","",IFERROR(INDEX(G$6:G$28,MATCH($J7,$C$6:$C$28,0)),"?")) | O7: =IF($J7="","",TEXTJOIN(" | ",TRUE,IF($C$6:$C$28=$J7,$B$6:$B$28,"")))
A8: 3 | B8: Gwadar Port | I8: 3 | K8: =IF($J8="","",IFERROR(INDEX(D$6:D$28,MATCH($J8,$C$6:$C$28,0)),"?")) | L8: =IF($J8="","",IFERROR(INDEX(E$6:E$28,MATCH($J8,$C$6:$C$28,0)),"?")) | M8: =IF($J8="","",IFERROR(INDEX(F$6:F$28,MATCH($J8,$C$6:$C$28,0)),"?")) | N8: =IF($J8="","",IFERROR(INDEX(G$6:G$28,MATCH($J8,$C$6:$C$28,0)),"?")) | O8: =IF($J8="","",TEXTJOIN(" | ",TRUE,IF($C$6:$C$28=$J8,$B$6:$B$28,"")))
A9: 4 | B9: Karachi Cantt | I9: 4 | K9: =IF($J9="","",IFERROR(INDEX(D$6:D$28,MATCH($J9,$C$6:$C$28,0)),"?")) | L9: =IF($J9="","",IFERROR(INDEX(E$6:E$28,MATCH($J9,$C$6:$C$28,0)),"?")) | M9: =IF($J9="","",IFERROR(INDEX(F$6:F$28,MATCH($J9,$C$6:$C$28,0)),"?")) | N9: =IF($J9="","",IFERROR(INDEX(G$6:G$28,MATCH($J9,$C$6:$C$28,0)),"?")) | O9: =IF($J9="","",TEXTJOIN(" | ",TRUE,IF($C$6:$C$28=$J9,$B$6:$B$28,"")))
A10: 5 | B10: Pipri Marshalling Yard | I10: 5 | K10: =IF($J10="","",IFERROR(INDEX(D$6:D$28,MATCH($J10,$C$6:$C$28,0)),"?")) | L10: =IF($J10="","",IFERROR(INDEX(E$6:E$28,MATCH($J10,$C$6:$C$28,0)),"?")) | M10: =IF($J10="","",IFERROR(INDEX(F$6:F$28,MATCH($J10,$C$6:$C$28,0)),"?")) | N10: =IF($J10="","",IFERROR(INDEX(G$6:G$28,MATCH($J10,$C$6:$C$28,0)),"?")) | O10: =IF($J10="","",TEXTJOIN(" | ",TRUE,IF($C$6:$C$28=$J10,$B$6:$B$28,"")))
A11: 6 | B11: Lahore | I11: 6 | K11: =IF($J11="","",IFERROR(INDEX(D$6:D$28,MATCH($J11,$C$6:$C$28,0)),"?")) | L11: =IF($J11="","",IFERROR(INDEX(E$6:E$28,MATCH($J11,$C$6:$C$28,0)),"?")) | M11: =IF($J11="","",IFERROR(INDEX(F$6:F$28,MATCH($J11,$C$6:$C$28,0)),"?")) | N11: =IF($J11="","",IFERROR(INDEX(G$6:G$28,MATCH($J11,$C$6:$C$28,0)),"?")) | O11: =IF($J11="","",TEXTJOIN(" | ",TRUE,IF($C$6:$C$28=$J11,$B$6:$B$28,"")))
A12: 7 | B12: Karachi | I12: 7 | K12: =IF($J12="","",IFERROR(INDEX(D$6:D$28,MATCH($J12,$C$6:$C$28,0)),"?")) | L12: =IF($J12="","",IFERROR(INDEX(E$6:E$28,MATCH($J12,$C$6:$C$28,0)),"?")) | M12: =IF($J12="","",IFERROR(INDEX(F$6:F$28,MATCH($J12,$C$6:$C$28,0)),"?")) | N12: =IF($J12="","",IFERROR(INDEX(G$6:G$28,MATCH($J12,$C$6:$C$28,0)),"?")) | O12: =IF($J12="","",TEXTJOIN(" | ",TRUE,IF($C$6:$C$28=$J12,$B$6:$B$28,"")))
A13: 8 | B13: Multan | I13: 8 | K13: =IF($J13="","",IFERROR(INDEX(D$6:D$28,MATCH($J13,$C$6:$C$28,0)),"?")) | L13: =IF($J13="","",IFERROR(INDEX(E$6:E$28,MATCH($J13,$C$6:$C$28,0)),"?")) | M13: =IF($J13="","",IFERROR(INDEX(F$6:F$28,MATCH($J13,$C$6:$C$28,0)),"?")) | N13: =IF($J13="","",IFERROR(INDEX(G$6:G$28,MATCH($J13,$C$6:$C$28,0)),"?")) | O13: =IF($J13="","",TEXTJOIN(" | ",TRUE,IF($C$6:$C$28=$J13,$B$6:$B$28,"")))
A14: 9 | B14: Islamabad | I14: 9 | K14: =IF($J14="","",IFERROR(INDEX(D$6:D$28,MATCH($J14,$C$6:$C$28,0)),"?")) | L14: =IF($J14="","",IFERROR(INDEX(E$6:E$28,MATCH($J14,$C$6:$C$28,0)),"?")) | M14: =IF($J14="","",IFERROR(INDEX(F$6:F$28,MATCH($J14,$C$6:$C$28,0)),"?")) | N14: =IF($J14="","",IFERROR(INDEX(G$6:G$28,MATCH($J14,$C$6:$C$28,0)),"?")) | O14: =IF($J14="","",TEXTJOIN(" | ",TRUE,IF($C$6:$C$28=$J14,$B$6:$B$28,"")))
A15: 10 | B15: Quetta | I15: 10 | K15: =IF($J15="","",IFERROR(INDEX(D$6:D$28,MATCH($J15,$C$6:$C$28,0)),"?")) | L15: =IF($J15="","",IFERROR(INDEX(E$6:E$28,MATCH($J15,$C$6:$C$28,0)),"?")) | M15: =IF($J15="","",IFERROR(INDEX(F$6:F$28,MATCH($J15,$C$6:$C$28,0)),"?")) | N15: =IF($J15="","",IFERROR(INDEX(G$6:G$28,MATCH($J15,$C$6:$C$28,0)),"?")) | O15: =IF($J15="","",TEXTJOIN(" | ",TRUE,IF($C$6:$C$28=$J15,$B$6:$B$28,"")))
A16: 11 | B16: Faisalabad | I16: 11 | K16: =IF($J16="","",IFERROR(INDEX(D$6:D$28,MATCH($J16,$C$6:$C$28,0)),"?")) | L16: =IF($J16="","",IFERROR(INDEX(E$6:E$28,MATCH($J16,$C$6:$C$28,0)),"?")) | M16: =IF($J16="","",IFERROR(INDEX(F$6:F$28,MATCH($J16,$C$6:$C$28,0)),"?")) | N16: =IF($J16="","",IFERROR(INDEX(G$6:G$28,MATCH($J16,$C$6:$C$28,0)),"?")) | O16: =IF($J16="","",TEXTJOIN(" | ",TRUE,IF($C$6:$C$28=$J16,$B$6:$B$28,"")))
A17: 12 | B17: Rawalpindi | I17: 12 | K17: =IF($J17="","",IFERROR(INDEX(D$6:D$28,MATCH($J17,$C$6:$C$28,0)),"?")) | L17: =IF($J17="","",IFERROR(INDEX(E$6:E$28,MATCH($J17,$C$6:$C$28,0)),"?")) | M17: =IF($J17="","",IFERROR(INDEX(F$6:F$28,MATCH($J17,$C$6:$C$28,0)),"?")) | N17: =IF($J17="","",IFERROR(INDEX(G$6:G$28,MATCH($J17,$C$6:$C$28,0)),"?")) | O17: =IF($J17="","",TEXTJOIN(" | ",TRUE,IF($C$6:$C$28=$J17,$B$6:$B$28,"")))
... A20: 15 | B20: Sialkot Dry Port | I20: -1 | K20: =IF($J20="","",IFERROR(INDEX(D$6:D$28,MATCH($J20,$C$6:$C$28,0)),"?")) | L20: =IF($J20="","",IFERROR(INDEX(E$6:E$28,MATCH($J20,$C$6:$C$28,0)),"?")) | M20: =IF($J20="","",IFERROR(INDEX(F$6:F$28,MATCH($J20,$C$6:$C$28,0)),"?")) | N20: =IF($J20="","",IFERROR(INDEX(G$6:G$28,MATCH($J20,$C$6:$C$28,0)),"?")) | O20: =IF($J20="","",TEXTJOIN(" | ",TRUE,IF($C$6:$C$28=$J20,$B$6:$B$28,"")))
A21: 16 | B21: Peshawar
A22: 17 | B22: Islamabad Dry Port
A23: 18 | B23: Hyderabad
A24: 19 | B24: Peshawar Cantt
A25: 20 | B25: Sukkur
A26: 21 | B26: Sialkot
A27: 22 | B27: Gujranwala
A28: 23 | B28: Abbottabad
A30: SELF-CHECK · THESE THREE MUST ALL PASS BEFORE YOU START T5
C31: Check | D31: Expected | E31: Your result | F31: Pass?
C32: Distinct conformed city names in Block 1 | D32: 14 | E32: =SUMPRODUCT((C6:C28<>"")/COUNTIF(C6:C28,C6:C28&"")) | F32: =IF(E32=D32,"✔ pass","✘ fix") | G32: If you get 15 or more you have left two spellings of one city apart. If 13 or fewer you have merged two genuinely different cities — check Islamabad against Rawalpindi.
C33: Raw strings that map to Karachi | D33: 5 | E33: =COUNTIF(C6:C28,"Karachi") | F33: =IF(E33=D33,"✔ pass","✘ fix") | G33: Karachi Port, Port Qasim, Karachi Cantt, Pipri Marshalling Yard and plain Karachi are five facilities in one city. Merging them is the whole point; getting 2 means you kept the rail yards separate.
C34: Rows in DimCity, excluding the Unknown row | D34: 14 | E34: =COUNTIF(I6:I20,">0") | F34: =IF(E34=D34,"✔ pass","✘ fix") | G34: Fourteen cities plus one reserved row with key -1. The -1 row is not optional — T6 needs somewhere to point when a future file arrives with a city nobody has mapped.
A36: THE JUDGEMENT CALL — ANSWER BEFORE YOU MOVE ON
B37: Pipri Marshalling Yard is 40 km from Karachi Cantt and is a separate railway facility. You merged it into Karachi. Name one business decision that choice quietly made for PakFreight.
B39: Islamabad is its own territory, not part of Punjab. What breaks in a provincial report if you map it to Punjab, and what breaks if you leave Province blank?
B41: A new file arrives next month with 'KHI Port Trust'. Walk through exactly what has to happen, in order, for it to appear correctly in a report.
A44: Marking, 20 marks: conforming map 8 · provinces and regions correct 4 · DimCity built with a reused -1 row 4 · the three judgement questions 4. Karachi must be CityKey 1 everywhere it appears for the rest of the workbook to reconcile.

Sheet T5 Other Dimensions
A1: T5 · DimRoute, DimMode, DimStatus, DimDate
A2: Four more dimensions. One of them contains a trap that the lecture slides walk straight past — find it in Block A before you fill anything in.
A4: BLOCK A · DIMROUTE — 20 ROWS. BUT THE RAW DATA HAS 30 DISTINCT PAIRS.
A5: The lab brief says: 'Keep Origin and Destination, Remove Duplicates → 20 rows.' Try it on Shipments_Unified and you get 30. Column I below lists all 30 raw pairs. Before you build anything: write down why the two numbers differ, and which operation has to happen first.
B7: Your answer:
A9: # | B9: RouteKey | C9: OriginCityKey | D9: DestCityKey | E9: RouteName | F9: Corridor | G9: DistanceBand | I9: The 30 RAW origin → destination pairs (grey)
A10: 1 | B10: 1 | I10: Karachi Port → Lahore Dry Port
A11: 2 | B11: 2 | I11: Port Qasim → Faisalabad Dry Port
A12: 3 | B12: 3 | I12: Gwadar Port → Quetta
A13: 4 | B13: 4 | I13: Port Qasim → Multan
A14: 5 | B14: 5 | I14: Karachi Port → Sialkot Dry Port
A15: 6 | B15: 6 | I15: Port Qasim → Lahore Dry Port
A16: 7 | B16: 7 | I16: Karachi Port → Peshawar
A17: 8 | B17: 8 | I17: Gwadar Port → Karachi Cantt
A18: 9 | B18: 9 | I18: Port Qasim → Islamabad Dry Port
A19: 10 | B19: 10 | I19: Karachi Port → Hyderabad
A20: 11 | B20: 11 | I20: Karachi Cantt → Lahore
A21: 12 | B21: 12 | I21: Karachi Cantt → Rawalpindi
... A29: 20 | B29: 20 | I29: Lahore → Islamabad
B30: -1 | I30: Karachi → Hyderabad
I31: Lahore → Faisalabad
I32: Multan → Lahore
I33: Islamabad → Peshawar
I34: Karachi → Sukkur
I35: Lahore → Sialkot
I36: Quetta → Karachi
I37: Faisalabad → Multan
I38: Lahore → Gujranwala
I39: Rawalpindi → Abbottabad
I40: 30 raw pairs → 20 conformed routes
B41: Check · distinct RouteName values | E41: =SUMPRODUCT((E10:E30<>"")/COUNTIF(E10:E30,E10:E30&"")) | F41: 21 | G41: =IF(E41=F41,"✔ pass","✘ fix") | I41: 20 real routes + 1 Unknown row = 21 distinct names.
A43: BLOCK B · DIMMODE AND DIMSTATUS — TYPED BY HAND. THIS IS REFERENCE DATA, NOT SOURCE DATA.
B44: ModeKey | C44: ModeName | D44: Carrier | E44: TonnageClass | F44: CostProfile | G44: Containerised? | K44: StatusKey | L44: StatusName | M44: IsClosed | N44: IsException | O44: DisplayOrder
B45: 1 | K45: 1
B46: 2 | K46: 2
B47: 3 | K47: 3
B48: -1 | K48: -1
B49: Both tables carry a row with key -1 called Unknown. It is not decoration: in T6 every lookup is a LEFT join, and a row whose mode nobody recognises must land somewhere visible rather than disappear. A fact row pointing at Unknown is a bug you can count; a fact row silently dropped is a bug you discover in a board meeting.
A51: BLOCK C · DIMDATE — 28 ROWS FOR FEBRUARY 2026, INCLUDING THE QUIET DAYS
B52: DateKey | C52: FullDate | D52: Year | E52: Quarter | F52: MonthNumber | G52: MonthName | I52: DayOfMonth | K52: DayNumber | L52: DayName | M52: IsWeekend | N52: IsHoliday | O52: Shipments that day | P52: In fact table?
...

Sheet T6 FactShipment
A1: T6 · Build FactShipment — Swap Every Text Column for an Integer Key
A2: Left of the gap: Shipments_Unified exactly as Week 2 left it. Right of the gap: the fact table. Row 6 is worked for you — copy it down to row 39. The rule you must not break: no descriptive text crosses the gap.
A3: Row 6 is worked for you — copy J6:S6 down to row 39. Until T4 and T5 are filled in, every key in row 6 reads -1. That is not an error: it is the Unknown row doing its job, because IFERROR sends an unmatched lookup to key -1 instead of losing the fact row. Watch them turn into real keys as you complete the dimensions.
A4: SOURCE · grey, do not edit | J4: FACTSHIPMENT · six keys + one degenerate + three measures | U4: EXCEL-ONLY SCRATCH
A5: ShipmentID | B5: ShipDate | C5: Origin | D5: Destination | E5: Source | F5: Status | G5: WeightKG | H5: CostPKR | J5: DateKey | K5: OriginCityKey | L5: DestCityKey | M5: RouteKey | N5: ModeKey | O5: StatusKey | P5: ShipmentID | Q5: WeightKG | R5: FreightCostPKR | S5: Count | U5: OriginProvince | V5: ModeName
A6: MR-1001 | B6: 46054 | C6: Karachi Port | D6: Lahore Dry Port | E6: Marine | F6: Delivered | G6: 18000 | H6: 142000 | J6: =YEAR(B6)*10000+MONTH(B6)*100+DAY(B6) | K6: =IFERROR(INDEX('T4 DimCity'!$I$6:$I$20,MATCH(INDEX('T4 DimCity'!$C$6:$C$28,MATCH(C6,'T4 DimCity'!$B$6:$B$28,0)),'T4 DimCity'!$J$6:$J$20,0)),-1) | L6: =IFERROR(INDEX('T4 DimCity'!$I$6:$I$20,MATCH(INDEX('T4 DimCity'!$C$6:$C$28,MATCH(D6,'T4 DimCity'!$B$6:$B$28,0)),'T4 DimCity'!$J$6:$J$20,0)),-1) | M6: =IFERROR(INDEX('T5 Other Dimensions'!$B$10:$B$30,MATCH(INDEX('T4 DimCity'!$C$6:$C$28,MATCH(C6,'T4 DimCity'!$B$6:$B$28,0))&" -> "&INDEX('T4 DimCity'!$C$6:$C$28,MATCH(D6,'T4 DimCity'!$B$6:$B$28,0)),'T5 Other Dimensions'!$E$10:$E$30,0)),-1) | N6: =IFERROR(INDEX('T5 Other Dimensions'!$B$45:$B$48,MATCH(E6,'T5 Other Dimensions'!$C$45:$C$48,0)),-1) | O6: =IFERROR(INDEX('T5 Other Dimensions'!$K$45:$K$48,MATCH(F6,'T5 Other Dimensions'!$L$45:$L$48,0)),-1) | P6: =A6 | Q6: =G6 | R6: =H6 | S6: 1 | U6: =IFERROR(INDEX('T4 DimCity'!$K$6:$K$20,MATCH(K6,'T4 DimCity'!$I$6:$I$20,0)),"?") | V6: =IFERROR(INDEX('T5 Other Dimensions'!$C$45:$C$48,MATCH(N6,'T5 Other Dimensions'!$B$45:$B$48,0)),"?")
A7: MR-1002 | B7: 46055 | C7: Port Qasim | D7: Faisalabad Dry Port | E7: Marine | F7: Delivered | G7: 22500 | H7: 171000 | U7: =IFERROR(INDEX('T4 DimCity'!$K$6:$K$20,MATCH(K7,'T4 DimCity'!$I$6:$I$20,0)),"?") | V7: =IFERROR(INDEX('T5 Other Dimensions'!$C$45:$C$48,MATCH(N7,'T5 Other Dimensions'!$B$45:$B$48,0)),"?")
A8: MR-1003 | B8: 46056 | C8: Karachi Port | D8: Lahore Dry Port | E8: Marine | F8: In Transit | G8: 15000 | H8: 119000 | U8: =IFERROR(INDEX('T4 DimCity'!$K$6:$K$20,MATCH(K8,'T4 DimCity'!$I$6:$I$20,0)),"?") | V8: =IFERROR(INDEX('T5 Other Dimensions'!$C$45:$C$48,MATCH(N8,'T5 Other Dimensions'!$B$45:$B$48,0)),"?")
A9: MR-1004 | B9: 46057 | C9: Gwadar Port | D9: Quetta | E9: Marine | F9: Delivered | G9: 20000 | H9: 188000 | U9: =IFERROR(INDEX('T4 DimCity'!$K$6:$K$20,MATCH(K9,'T4 DimCity'!$I$6:$I$20,0)),"?") | V9: =IFERROR(INDEX('T5 Other Dimensions'!$C$45:$C$48,MATCH(N9,'T5 Other Dimensions'!$B$45:$B$48,0)),"?")
A10: MR-1005 | B10: 46058 | C10: Port Qasim | D10: Multan | E10: Marine | F10: Delivered | G10: 16500 | H10: 128000 | U10: =IFERROR(INDEX('T4 DimCity'!$K$6:$K$20,MATCH(K10,'T4 DimCity'!$I$6:$I$20,0)),"?") | V10: =IFERROR(INDEX('T5 Other Dimensions'!$C$45:$C$48,MATCH(N10,'T5 Other Dimensions'!$B$45:$B$48,0)),"?")
A11: MR-1006 | B11: 46059 | C11: Karachi Port | D11: Sialkot Dry Port | E11: Marine | F11: Delayed | G11: 19000 | H11: 154000 | U11: =IFERROR(INDEX('T4 DimCity'!$K$6:$K$20,MATCH(K11,'T4 DimCity'!$I$6:$I$20,0)),"?") | V11: =IFERROR(INDEX('T5 Other Dimensions'!$C$45:$C$48,MATCH(N11,'T5 Other Dimensions'!$B$45:$B$48,0)),"?")
A12: MR-1007 | B12: 46060 | C12: Port Qasim | D12: Lahore Dry Port | E12: Marine | F12: Delivered | G12: 14000 | H12: 109000 | U12: =IFERROR(INDEX('T4 DimCity'!$K$6:$K$20,MATCH(K12,'T4 DimCity'!$I$6:$I$20,0)),"?") | V12: =IFERROR(INDEX('T5 Other Dimensions'!$C$45:$C$48,MATCH(N12,'T5 Other Dimensions'!$B$45:$B$48,0)),"?")
A13: MR-1008 | B13: 46062 | C13: Karachi Port | D13: Peshawar | E13: Marine | F13: In Transit | G13: 21000 | H13: 197000 | U13: =IFERROR(INDEX('T4 DimCity'!$K$6:$K$20,MATCH(K13,'T4 DimCity'!$I$6:$I$20,0)),"?") | V13: =IFERROR(INDEX('T5 Other Dimensions'!$C$45:$C$48,MATCH(N13,'T5 Other Dimensions'!$B$45:$B$48,0)),"?")
A14: MR-1009 | B14: 46063 | C14: Gwadar Port | D14: Karachi Cantt | E14: Marine | F14: Delivered | G14: 17500 | H14: 98000 | U14: =IFERROR(INDEX('T4 DimCity'!$K$6:$K$20,MATCH(K14,'T4 DimCity'!$I$6:$I$20,0)),"?") | V14: =IFERROR(INDEX('T5 Other Dimensions'!$C$45:$C$48,MATCH(N14,'T5 Other Dimensions'!$B$45:$B$48,0)),"?")
A15: MR-1010 | B15: 46064 | C15: Port Qasim | D15: Islamabad Dry Port | E15: Marine | F15: Delivered | G15: 15500 | H15: 139000 | U15: =IFERROR(INDEX('T4 DimCity'!$K$6:$K$20,MATCH(K15,'T4 DimCity'!$I$6:$I$20,0)),"?") | V15: =IFERROR(INDEX('T5 Other Dimensions'!$C$45:$C$48,MATCH(N15,'T5 Other Dimensions'!$B$45:$B$48,0)),"?")
A16: MR-1011 | B16: 46065 | C16: Karachi Port | D16: Hyderabad | E16: Marine | F16: In Transit | G16: 13500 | H16: 61000 | U16: =IFERROR(INDEX('T4 DimCity'!$K$6:$K$20,MATCH(K16,'T4 DimCity'!$I$6:$I$20,0)),"?") | V16: =IFERROR(INDEX('T5 Other Dimensions'!$C$45:$C$48,MATCH(N16,'T5 Other Dimensions'!$B$45:$B$48,0)),"?")
A17: MR-1012 | B17: 46066 | C17: Port Qasim | D17: Lahore Dry Port | E17: Marine | F17: Delivered | G17: 14000 | H17: 112000 | U17: =IFERROR(INDEX('T4 DimCity'!$K$6:$K$20,MATCH(K17,'T4 DimCity'!$I$6:$I$20,0)),"?") | V17: =IFERROR(INDEX('T5 Other Dimensions'!$C$45:$C$48,MATCH(N17,'T5 Other Dimensions'!$B$45:$B$48,0)),"?")
A18: RL-45012 | B18: 46056 | C18: Karachi Cantt | D18: Lahore | E18: Rail | F18: Delivered | G18: 32500 | H18: 285000 | U18: =IFERROR(INDEX('T4 DimCity'!$K$6:$K$20,MATCH(K18,'T4 DimCity'!$I$6:$I$20,0)),"?") | V18: =IFERROR(INDEX('T5 Other Dimensions'!$C$45:$C$48,MATCH(N18,'T5 Other Dimensions'!$B$45:$B$48,0)),"?")
... A39: RD-512 | B39: 46066 | C39: Rawalpindi | D39: Abbottabad | E39: Road | F39: Delivered | G39: 5800 | H39: 45000 | U39: =IFERROR(INDEX('T4 DimCity'!$K$6:$K$20,MATCH(K39,'T4 DimCity'!$I$6:$I$20,0)),"?") | V39: =IFERROR(INDEX('T5 Other Dimensions'!$C$45:$C$48,MATCH(N39,'T5 Other Dimensions'!$B$45:$B$48,0)),"?")
P40: TOTAL | Q40: =SUM(Q6:Q39) | R40: =SUM(R6:R39) | S40: =SUM(S6:S39)
A42: Columns U and V are a scratch pad, NOT part of the fact table. Excel has no relationships, so T7 needs the province and the mode name as text to build a matrix with SUMIFS. In Power BI the relationship does this for you and these two columns must not exist in your .pbix — if they do, you have put descriptive text back into a fact table and undone the whole exercise.
A44: THE THREE QUESTIONS THIS TASK IS REALLY ASKING
A45: Every lookup above is wrapped in IFERROR(…, -1) instead of being left to fail. Name what that buys you and what it costs you.
A47: Columns C to F still hold the text. Why do they not cross the gap into the fact table?
A49: ShipmentID is in the fact table but joins to nothing. Defend keeping it.
A52: Marking, 15 marks: six key columns correct 9 · measures and degenerate key 3 · the three questions 3. A hard-typed key column instead of a lookup scores zero for that column — the point is the join, not the digit.

Sheet T7 Reconcile
A1: T7 · Reconcile — Thirteen Checks, All Thirteen Must Pass
A2: The reshaping must not change a single kilogram. Reconciliation is not a formality: it is the last moment at which you can still find the mistake cheaply.
A4: # | B4: Check | C4: Expected | D4: Your result | E4: Pass? | F4: If it does not match, look here first
A5: 1 | B5: Row count of FactShipment | C5: 34 | D5: =COUNT('T6 FactShipment'!$J$6:$J$39) | E5: =IF(D5=C5,"✔ pass","✘ fix") | F5: You dropped rows in a lookup, or you duplicated one to fit a dimension. A changed row count means the grain moved.
A6: 2 | B6: Grand total, WeightKG | C6: 578650 | D6: =SUM('T6 FactShipment'!$Q$6:$Q$39) | E6: =IF(D6=C6,"✔ pass","✘ fix") | F6: Rail is still in tonnes (a factor of 1,000 missing), or the rd-505 duplicate came back, or the Road TOTAL row survived staging.
A7: 3 | B7: Grand total, FreightCostPKR | C7: 4808000 | D7: =SUM('T6 FactShipment'!$R$6:$R$39) | E7: =IF(D7=C7,"✔ pass","✘ fix") | F7: Same causes as the weight check. Costs are additive currency — there is no rounding excuse.
A8: 4 | B8: Shipment legs (SUM of Count) | C8: 34 | D8: =SUM('T6 FactShipment'!$S$6:$S$39) | E8: =IF(D8=C8,"✔ pass","✘ fix") | F8: A measure problem, not a data problem — check that ShipmentCount is 1 on every row, including the last one.
A9: 5 | B9: Distinct ShipmentID values | C9: 34 | D9: =SUMPRODUCT(('T6 FactShipment'!$P$6:$P$39<>"")/COUNTIF('T6 FactShipment'!$P$6:$P$39,'T6 FactShipment'!$P$6:$P$39&"")) | E9: =IF(D9=C9,"✔ pass","✘ fix") | F9: Equal to the leg count here because no consignment was split. The day they differ, the grain sentence has to say which one a row is.
A10: 6 | B10: Rows in DimCity (excluding Unknown) | C10: 14 | D10: =COUNTIF('T4 DimCity'!$I$6:$I$20,">0") | E10: =IF(D10=C10,"✔ pass","✘ fix") | F10: Your conforming map is incomplete — you still have 23, or some number in between.
A11: 7 | B11: Rows in DimRoute (excluding Unknown) | C11: 20 | D11: =COUNTIF('T5 Other Dimensions'!$B$10:$B$30,">0") | E11: =IF(D11=C11,"✔ pass","✘ fix") | F11: 30 means you deduplicated the raw strings instead of the conformed city keys. Go back to T5 Block A.
A12: 8 | B12: Rows in DimDate | C12: 28 | D12: =COUNTA('T5 Other Dimensions'!$C$53:$C$80) | E12: =IF(D12=C12,"✔ pass","✘ fix") | F12: 12 means you generated only the dates that appear in the fact table. A date dimension with holes breaks every time-intelligence function.
A13: 9 | B13: WeightKG for Sindh / Marine | C13: 169000 | D13: =SUMIFS('T6 FactShipment'!$Q$6:$Q$39,'T6 FactShipment'!$U$6:$U$39,"Sindh",'T6 FactShipment'!$V$6:$V$39,"Marine") | E13: =IF(D13=C13,"✔ pass","✘ fix") | F13: If you got 206,500 you mapped Gwadar Port to Karachi. Gwadar is in Balochistan, and it is the one conforming decision students get wrong most often.
A14: 10 | B14: WeightKG for Punjab / Road | C14: 44100 | D14: =SUMIFS('T6 FactShipment'!$Q$6:$Q$39,'T6 FactShipment'!$U$6:$U$39,"Punjab",'T6 FactShipment'!$V$6:$V$39,"Road") | E14: =IF(D14=C14,"✔ pass","✘ fix") | F14: Check that Lahore, Faisalabad, Multan, Sialkot, Gujranwala and Rawalpindi all map to Punjab — and that Islamabad does NOT.
A15: 11 | B15: WeightKG for Sindh, all modes | C15: 484350 | D15: =SUMIFS('T6 FactShipment'!$Q$6:$Q$39,'T6 FactShipment'!$U$6:$U$39,"Sindh") | E15: =IF(D15=C15,"✔ pass","✘ fix") | F15: 83.7% of everything PakFreight moved. If it is lower, some Karachi alias is still its own city.
A16: 12 | B16: Fact rows pointing at an Unknown key (-1) | C16: 0 | D16: =COUNTIF('T6 FactShipment'!$K$6:$K$39,-1)+COUNTIF('T6 FactShipment'!$L$6:$L$39,-1)+COUNTIF('T6 FactShipment'!$M$6:$M$39,-1)+COUNTIF('T6 FactShipment'!$N$6:$N$39,-1)+COUNTIF('T6 FactShipment'!$O$6:$O$39,-1) | E16: =IF(D16=C16,"✔ pass","✘ fix") | F16: A lookup failed and IFERROR caught it. Which column, and which row? The -1 row exists so this is a number you can read, not a row you lost.
A17: 13 | B17: Cost per KG, grand total | C17: 8.31 | D17: =SUM('T6 FactShipment'!$R$6:$R$39)/SUM('T6 FactShipment'!$Q$6:$Q$39) | E17: =IF(ABS(D17-C17)<=0.005,"✔ pass","✘ fix") | F17: 8.06 means you averaged a ratio instead of dividing two sums. See T3 — this is the same 3% error, now wearing a dashboard.
B19: CHECKS PASSING | C19: =COUNTIF(E5:E17,"✔*")&" / 13" | D19: =IF(COUNTIF(E5:E17,"✔*")=13,"✔ SUBMIT","✘ NOT YET") | F19: Submitting with a single red cell loses all 8 marks for this task. Thirteen out of thirteen, or it is not done.
A21: THE DELIVERABLE MATRIX · TONNAGE BY ORIGIN PROVINCE AND MODE
A22: Build this in Power BI too: Province on rows, Mode on columns, Total Weight KG in values. The grand total must read 578,650 kg exactly.
B23: Origin province | C23: Marine | D23: Rail | E23: Road | F23: Total
B24: Sindh | C24: =SUMIFS('T6 FactShipment'!$Q$6:$Q$39,'T6 FactShipment'!$U$6:$U$39,$B24,'T6 FactShipment'!$V$6:$V$39,"Marine") | D24: =SUMIFS('T6 FactShipment'!$Q$6:$Q$39,'T6 FactShipment'!$U$6:$U$39,$B24,'T6 FactShipment'!$V$6:$V$39,"Rail") | E24: =SUMIFS('T6 FactShipment'!$Q$6:$Q$39,'T6 FactShipment'!$U$6:$U$39,$B24,'T6 FactShipment'!$V$6:$V$39,"Road") | F24: =SUM(C24:E24)
B25: Punjab | C25: =SUMIFS('T6 FactShipment'!$Q$6:$Q$39,'T6 FactShipment'!$U$6:$U$39,$B25,'T6 FactShipment'!$V$6:$V$39,"Marine") | D25: =SUMIFS('T6 FactShipment'!$Q$6:$Q$39,'T6 FactShipment'!$U$6:$U$39,$B25,'T6 FactShipment'!$V$6:$V$39,"Rail") | E25: =SUMIFS('T6 FactShipment'!$Q$6:$Q$39,'T6 FactShipment'!$U$6:$U$39,$B25,'T6 FactShipment'!$V$6:$V$39,"Road") | F25: =SUM(C25:E25)
B26: Balochistan | C26: =SUMIFS('T6 FactShipment'!$Q$6:$Q$39,'T6 FactShipment'!$U$6:$U$39,$B26,'T6 FactShipment'!$V$6:$V$39,"Marine") | D26: =SUMIFS('T6 FactShipment'!$Q$6:$Q$39,'T6 FactShipment'!$U$6:$U$39,$B26,'T6 FactShipment'!$V$6:$V$39,"Rail") | E26: =SUMIFS('T6 FactShipment'!$Q$6:$Q$39,'T6 FactShipment'!$U$6:$U$39,$B26,'T6 FactShipment'!$V$6:$V$39,"Road") | F26: =SUM(C26:E26)
B27: Khyber Pakhtunkhwa | C27: =SUMIFS('T6 FactShipment'!$Q$6:$Q$39,'T6 FactShipment'!$U$6:$U$39,$B27,'T6 FactShipment'!$V$6:$V$39,"Marine") | D27: =SUMIFS('T6 FactShipment'!$Q$6:$Q$39,'T6 FactShipment'!$U$6:$U$39,$B27,'T6 FactShipment'!$V$6:$V$39,"Rail") | E27: =SUMIFS('T6 FactShipment'!$Q$6:$Q$39,'T6 FactShipment'!$U$6:$U$39,$B27,'T6 FactShipment'!$V$6:$V$39,"Road") | F27: =SUM(C27:E27)
B28: Islamabad ICT | C28: =SUMIFS('T6 FactShipment'!$Q$6:$Q$39,'T6 FactShipment'!$U$6:$U$39,$B28,'T6 FactShipment'!$V$6:$V$39,"Marine") | D28: =SUMIFS('T6 FactShipment'!$Q$6:$Q$39,'T6 FactShipment'!$U$6:$U$39,$B28,'T6 FactShipment'!$V$6:$V$39,"Rail") | E28: =SUMIFS('T6 FactShipment'!$Q$6:$Q$39,'T6 FactShipment'!$U$6:$U$39,$B28,'T6 FactShipment'!$V$6:$V$39,"Road") | F28: =SUM(C28:E28)
B29: Grand total | C29: =SUM(C24:C28) | D29: =SUM(D24:D28) | E29: =SUM(E24:E28) | F29: =SUM(F24:F28)
B30: Reconciles to 578,650? | F30: =IF(F29=578650,"✔ pass","✘ fix")
A31: Read the Khyber Pakhtunkhwa row: zero. PakFreight moved 61,900 kg INTO Peshawar and Abbottabad in February and nothing out of them, and this matrix is built on OriginCityKey. The number is correct, and the conclusion a reader draws from it — 'KP is not part of our network' — is false. A role-playing dimension is exactly this: the same DimCity answers two different questions, and the active relationship silently decides which one you asked. Rebuild the matrix on DestCityKey and KP reads 61,900 kg. In Power BI that is the USERELATIONSHIP bonus on slide 47.
A33: THE LAST QUESTION · WRITE IT BEFORE YOU SUBMIT
A34: Every one of the thirteen checks above passes and your matrix totals 578,650 kg. In two or three lines: name one thing that could still be wrong with this model that no check on this sheet would ever catch.
A38: Marking, 8 marks: thirteen checks passing 5 (all or nothing) · the matrix 1 · the last question 2.
